<?xml version="1.0" encoding="utf-8"?>
<!-- This URDF was automatically created by SolidWorks to URDF Exporter! Originally created by Stephen Brawner (brawner@gmail.com) 
     Commit Version: 1.6.0-4-g7f85cfe  Build Version: 1.6.7995.38578
     For more information, please see http://wiki.ros.org/sw_urdf_exporter -->
<robot
  name="audix">
  <link
    name="base_link">
    <inertial>
      <origin
        xyz="-0.165425609192592 -0.149974396919815 0.0555112241125014"
        rpy="0 0 0" />
      <mass
        value="2.23789814285684" />
      <inertia
        ixx="0.0100668608395496"
        ixy="3.41741618462387E-05"
        ixz="8.32772399082318E-05"
        iyy="0.0114849385643874"
        iyz="8.93952677484566E-05"
        izz="0.0190387521155491" />
    </inertial>
    <visual>
      <origin
        xyz="0 0 0"
        rpy="0 0 0" />
      <geometry>
        <mesh
          filename="package://audix/meshes/base_link.STL" />
      </geometry>
      <material
        name="">
        <color
          rgba="0.792156862745098 0.819607843137255 0.933333333333333 1" />
      </material>
    </visual>
    <collision>
      <origin
        xyz="0 0 0"
        rpy="0 0 0" />
      <geometry>
        <mesh
          filename="package://audix/meshes/base_link.STL" />
      </geometry>
    </collision>
  </link>
  <link
    name="front_left_wheel_link">
    <inertial>
      <origin
        xyz="2.17268698310402E-06 2.05342648856854E-07 -0.00553115532802828"
        rpy="0 0 0" />
      <mass
        value="0.131907084296385" />
      <inertia
        ixx="2.27621274494277E-05"
        ixy="-1.02524646272199E-09"
        ixz="1.96761982827681E-10"
        iyy="2.27707903666074E-05"
        iyz="-1.73299082188491E-09"
        izz="2.86732755656157E-05" />
    </inertial>
    <visual>
      <origin
        xyz="0 0 0"
        rpy="0 0 0" />
      <geometry>
        <mesh
          filename="package://audix/meshes/front_left_wheel_link.STL" />
      </geometry>
      <material
        name="">
        <color
          rgba="0.792156862745098 0.819607843137255 0.933333333333333 1" />
      </material>
    </visual>
    <collision>
      <origin
        xyz="0 0 0"
        rpy="0 0 0" />
      <geometry>
        <mesh
          filename="package://audix/meshes/front_left_wheel_link.STL" />
      </geometry>
    </collision>
  </link>
  <joint
    name="front_left_wheel_joint"
    type="continuous">
    <origin
      xyz="-0.250000000005374 -0.307389999999985 0.024999999989585"
      rpy="1.57079632679489 0 0" />
    <parent
      link="base_link" />
    <child
      link="front_left_wheel_link" />
    <axis
      xyz="0 0 -1" />
  </joint>
  <link
    name="front_right_wheel_link">
    <inertial>
      <origin
        xyz="9.66289620374372E-07 -2.18301833003476E-06 0.005591563250399"
        rpy="0 0 0" />
      <mass
        value="0.131907400590731" />
      <inertia
        ixx="2.2769646502052E-05"
        ixy="3.23471270264869E-09"
        ixz="1.61245288615068E-09"
        iyy="2.27636755981895E-05"
        iyz="6.6623654841971E-10"
        izz="2.86736671226467E-05" />
    </inertial>
    <visual>
      <origin
        xyz="0 0 0"
        rpy="0 0 0" />
      <geometry>
        <mesh
          filename="package://audix/meshes/front_right_wheel_link.STL" />
      </geometry>
      <material
        name="">
        <color
          rgba="0.792156862745098 0.819607843137255 0.933333333333333 1" />
      </material>
    </visual>
    <collision>
      <origin
        xyz="0 0 0"
        rpy="0 0 0" />
      <geometry>
        <mesh
          filename="package://audix/meshes/front_right_wheel_link.STL" />
      </geometry>
    </collision>
  </link>
  <joint
    name="front_right_wheel_joint"
    type="continuous">
    <origin
      xyz="-0.250000000005375 0.00739000000001477 0.0249999999895845"
      rpy="1.57079632679489 0 0" />
    <parent
      link="base_link" />
    <child
      link="front_right_wheel_link" />
    <axis
      xyz="0 0 1" />
  </joint>
  <link
    name="back_right_wheel_link">
    <inertial>
      <origin
        xyz="3.93598461267963E-07 -2.20615013937081E-06 0.00553103387698972"
        rpy="0 0 0" />
      <mass
        value="0.131907129758154" />
      <inertia
        ixx="2.27705864434052E-05"
        ixy="1.74920520754187E-09"
        ixz="-1.70044123207189E-09"
        iyy="2.27624163985454E-05"
        iyz="-4.12707157447266E-10"
        izz="2.86733556916648E-05" />
    </inertial>
    <visual>
      <origin
        xyz="0 0 0"
        rpy="0 0 0" />
      <geometry>
        <mesh
          filename="package://audix/meshes/back_right_wheel_link.STL" />
      </geometry>
      <material
        name="">
        <color
          rgba="0.792156862745098 0.819607843137255 0.933333333333333 1" />
      </material>
    </visual>
    <collision>
      <origin
        xyz="0 0 0"
        rpy="0 0 0" />
      <geometry>
        <mesh
          filename="package://audix/meshes/back_right_wheel_link.STL" />
      </geometry>
    </collision>
  </link>
  <joint
    name="back_right_wheel_joint"
    type="continuous">
    <origin
      xyz="-0.0700000000053771 0.00739000000001488 0.0249999999906142"
      rpy="1.57079632679489 0 0" />
    <parent
      link="base_link" />
    <child
      link="back_right_wheel_link" />
    <axis
      xyz="0 0 1" />
  </joint>
  <link
    name="back_left_wheel_link">
    <inertial>
      <origin
        xyz="2.27704030925091E-06 3.56143494868733E-07 -0.00559151540708869"
        rpy="0 0 0" />
      <mass
        value="0.131907545752213" />
      <inertia
        ixx="2.27625324063538E-05"
        ixy="-1.51398514697908E-09"
        ixz="-3.69564399113687E-10"
        iyy="2.27707651443182E-05"
        iyz="1.71638394759723E-09"
        izz="2.86736357556112E-05" />
    </inertial>
    <visual>
      <origin
        xyz="0 0 0"
        rpy="0 0 0" />
      <geometry>
        <mesh
          filename="package://audix/meshes/back_left_wheel_link.STL" />
      </geometry>
      <material
        name="">
        <color
          rgba="0.792156862745098 0.819607843137255 0.933333333333333 1" />
      </material>
    </visual>
    <collision>
      <origin
        xyz="0 0 0"
        rpy="0 0 0" />
      <geometry>
        <mesh
          filename="package://audix/meshes/back_left_wheel_link.STL" />
      </geometry>
    </collision>
  </link>
  <joint
    name="back_left_wheel_joint"
    type="continuous">
    <origin
      xyz="-0.0700000000053768 -0.307389999999987 0.024999999990612"
      rpy="1.57079632679489 0 0" />
    <parent
      link="base_link" />
    <child
      link="back_left_wheel_link" />
    <axis
      xyz="0 0 -1" />
  </joint>
  <link
    name="scissors_lift_base">
    <inertial>
      <origin
        xyz="0.0640804372939909 6.00038682641024E-06 0.0414333132682887"
        rpy="0 0 0" />
      <mass
        value="0.240484568927395" />
      <inertia
        ixx="0.000179982875589855"
        ixy="-4.87618131400979E-08"
        ixz="-3.47904212840419E-05"
        iyy="0.000579348711168266"
        iyz="-5.93888633785935E-10"
        izz="0.000667789961393891" />
    </inertial>
    <visual>
      <origin
        xyz="0 0 0"
        rpy="0 0 0" />
      <geometry>
        <mesh
          filename="package://audix/meshes/scissors_lift_base.STL" />
      </geometry>
      <material
        name="">
        <color
          rgba="0.792156862745098 0.819607843137255 0.933333333333333 1" />
      </material>
    </visual>
    <collision>
      <origin
        xyz="0 0 0"
        rpy="0 0 0" />
      <geometry>
        <mesh
          filename="package://audix/meshes/scissors_lift_base.STL" />
      </geometry>
    </collision>
  </link>
  <joint
    name="scissors_lift_base_fix"
    type="fixed">
    <origin
      xyz="-0.310000000005584 -0.150000000000003 0.0124999999899842"
      rpy="0 0 0" />
    <parent
      link="base_link" />
    <child
      link="scissors_lift_base" />
    <axis
      xyz="0 0 0" />
  </joint>
  <link
    name="bottom_stud_link">
    <inertial>
      <origin
        xyz="-9.6601817455369E-07 7.19407882932011E-07 -1.3007363775519E-06"
        rpy="0 0 0" />
      <mass
        value="0.00137057236420401" />
      <inertia
        ixx="1.36300739625947E-06"
        ixy="8.79532677974459E-12"
        ixz="-3.23276858235148E-14"
        iyy="2.72084887040127E-09"
        iyz="-7.18702250945327E-12"
        izz="1.36300692144801E-06" />
    </inertial>
    <visual>
      <origin
        xyz="0 0 0"
        rpy="0 0 0" />
      <geometry>
        <mesh
          filename="package://audix/meshes/bottom_stud_link.STL" />
      </geometry>
      <material
        name="">
        <color
          rgba="0.776470588235294 0.756862745098039 0.737254901960784 1" />
      </material>
    </visual>
    <collision>
      <origin
        xyz="0 0 0"
        rpy="0 0 0" />
      <geometry>
        <mesh
          filename="package://audix/meshes/bottom_stud_link.STL" />
      </geometry>
    </collision>
  </link>
  <joint
    name="bottom_stud_joint"
    type="prismatic">
    <origin
      xyz="0.137801664111862 -0.000349280592105594 0.0424989715630968"
      rpy="3.14159265358979 1.5707963267949 0" />
    <parent
      link="scissors_lift_base" />
    <child
      link="bottom_stud_link" />
    <axis
      xyz="0 0 1" />
    <limit
      lower="0"
      upper="0"
      effort="0"
      velocity="0" />
  </joint>
  <link
    name="right_link1">
    <inertial>
      <origin
        xyz="0.0589015692763848 0.0114282604442705 -1.94289029309402E-14"
        rpy="0 0 0" />
      <mass
        value="0.00615413438956677" />
      <inertia
        ixx="3.58514450718461E-07"
        ixy="-1.5129178963205E-06"
        ixz="-7.22387141838518E-21"
        iyy="7.86259408054773E-06"
        iyz="-1.6101409411266E-21"
        izz="8.19546630464299E-06" />
    </inertial>
    <visual>
      <origin
        xyz="0 0 0"
        rpy="0 0 0" />
      <geometry>
        <mesh
          filename="package://audix/meshes/right_link1.STL" />
      </geometry>
      <material
        name="">
        <color
          rgba="0.792156862745098 0.819607843137255 0.933333333333333 1" />
      </material>
    </visual>
    <collision>
      <origin
        xyz="0 0 0"
        rpy="0 0 0" />
      <geometry>
        <mesh
          filename="package://audix/meshes/right_link1.STL" />
      </geometry>
    </collision>
  </link>
  <joint
    name="right_joint1"
    type="revolute">
    <origin
      xyz="0 -0.0428492805921222 0"
      rpy="1.5707963267949 -1.5707963267949 0" />
    <parent
      link="bottom_stud_link" />
    <child
      link="right_link1" />
    <axis
      xyz="0 0 1" />
    <limit
      lower="0"
      upper="0"
      effort="0"
      velocity="0" />
  </joint>
  <link
    name="right_link4">
    <inertial>
      <origin
        xyz="0.0589015692765562 0.0114282604443096 2.1094237467878E-14"
        rpy="0 0 0" />
      <mass
        value="0.00615413438956673" />
      <inertia
        ixx="3.58514450684073E-07"
        ixy="-1.51291789623521E-06"
        ixz="-3.60554546235251E-20"
        iyy="7.86259408058206E-06"
        iyz="-7.54716058163533E-21"
        izz="8.19546630464294E-06" />
    </inertial>
    <visual>
      <origin
        xyz="0 0 0"
        rpy="0 0 0" />
      <geometry>
        <mesh
          filename="package://audix/meshes/right_link4.STL" />
      </geometry>
      <material
        name="">
        <color
          rgba="0.792156862745098 0.819607843137255 0.933333333333333 1" />
      </material>
    </visual>
    <collision>
      <origin
        xyz="0 0 0"
        rpy="0 0 0" />
      <geometry>
        <mesh
          filename="package://audix/meshes/right_link4.STL" />
      </geometry>
    </collision>
  </link>
  <joint
    name="right_joint4"
    type="revolute">
    <origin
      xyz="0.117803138552813 0.0228565208880633 -0.00499999999999967"
      rpy="3.14159265358979 0 3.14159265358979" />
    <parent
      link="right_link1" />
    <child
      link="right_link4" />
    <axis
      xyz="0 0 1" />
    <limit
      lower="0"
      upper="0"
      effort="0"
      velocity="0" />
  </joint>
  <link
    name="right_link5">
    <inertial>
      <origin
        xyz="0.0589015692761234 0.0110362235597465 0.00296764322724363"
        rpy="0 0 0" />
      <mass
        value="0.00615413438956677" />
      <inertia
        ixx="3.58514450718715E-07"
        ixy="-1.46101851743524E-06"
        ixz="-3.92868238370166E-07"
        iyy="7.88504016932886E-06"
        iyz="-8.34736640703394E-08"
        izz="8.17302021586157E-06" />
    </inertial>
    <visual>
      <origin
        xyz="0 0 0"
        rpy="0 0 0" />
      <geometry>
        <mesh
          filename="package://audix/meshes/right_link5.STL" />
      </geometry>
      <material
        name="">
        <color
          rgba="0.792156862745098 0.819607843137255 0.933333333333333 1" />
      </material>
    </visual>
    <collision>
      <origin
        xyz="0 0 0"
        rpy="0 0 0" />
      <geometry>
        <mesh
          filename="package://audix/meshes/right_link5.STL" />
      </geometry>
    </collision>
  </link>
  <joint
    name="right_joint5"
    type="revolute">
    <origin
      xyz="0.117803138552815 0.022856520887972 -0.00500000000000012"
      rpy="2.87890613213286 0 3.14159265358978" />
    <parent
      link="right_link4" />
    <child
      link="right_link5" />
    <axis
      xyz="0 0.259675848455465 -0.965695839138253" />
    <limit
      lower="0"
      upper="0"
      effort="0"
      velocity="0" />
  </joint>
  <link
    name="left_link1">
    <inertial>
      <origin
        xyz="0.0589015692763918 0.0114282604442722 -2.29816166097407E-14"
        rpy="0 0 0" />
      <mass
        value="0.0061541343895667" />
      <inertia
        ixx="3.5851445071867E-07"
        ixy="-1.51291789632101E-06"
        ixz="-6.31925059226189E-20"
        iyy="7.86259408054744E-06"
        iyz="-1.16050397546716E-20"
        izz="8.19546630464291E-06" />
    </inertial>
    <visual>
      <origin
        xyz="0 0 0"
        rpy="0 0 0" />
      <geometry>
        <mesh
          filename="package://audix/meshes/left_link1.STL" />
      </geometry>
      <material
        name="">
        <color
          rgba="0.792156862745098 0.819607843137255 0.933333333333333 1" />
      </material>
    </visual>
    <collision>
      <origin
        xyz="0 0 0"
        rpy="0 0 0" />
      <geometry>
        <mesh
          filename="package://audix/meshes/left_link1.STL" />
      </geometry>
    </collision>
  </link>
  <joint
    name="left_joint1"
    type="revolute">
    <origin
      xyz="0 0.0421507194078778 0"
      rpy="1.5707963267949 -1.5707963267949 0" />
    <parent
      link="bottom_stud_link" />
    <child
      link="left_link1" />
    <axis
      xyz="0 0 1" />
    <limit
      lower="0"
      upper="0"
      effort="0"
      velocity="0" />
  </joint>
  <link
    name="left_link4">
    <inertial>
      <origin
        xyz="0.058901569276552 0.0114282604443232 2.28705943072782E-14"
        rpy="0 0 0" />
      <mass
        value="0.00615413438956676" />
      <inertia
        ixx="3.58514450684054E-07"
        ixy="-1.51291789623515E-06"
        ixz="-1.01902841720759E-19"
        iyy="7.86259408058203E-06"
        iyz="-2.03433583444844E-20"
        izz="8.19546630464288E-06" />
    </inertial>
    <visual>
      <origin
        xyz="0 0 0"
        rpy="0 0 0" />
      <geometry>
        <mesh
          filename="package://audix/meshes/left_link4.STL" />
      </geometry>
      <material
        name="">
        <color
          rgba="0.792156862745098 0.819607843137255 0.933333333333333 1" />
      </material>
    </visual>
    <collision>
      <origin
        xyz="0 0 0"
        rpy="0 0 0" />
      <geometry>
        <mesh
          filename="package://audix/meshes/left_link4.STL" />
      </geometry>
    </collision>
  </link>
  <joint
    name="left_joint4"
    type="revolute">
    <origin
      xyz="0.117803138552813 0.0228565208880835 0.00499999999999956"
      rpy="3.14159265358979 0 3.14159265358979" />
    <parent
      link="left_link1" />
    <child
      link="left_link4" />
    <axis
      xyz="0 0 1" />
    <limit
      lower="0"
      upper="0"
      effort="0"
      velocity="0" />
  </joint>
  <link
    name="left_link5">
    <inertial>
      <origin
        xyz="0.0589015692761248 0.0114282604444132 -2.16493489801906E-14"
        rpy="0 0 0" />
      <mass
        value="0.00615413438956676" />
      <inertia
        ixx="3.58514450718512E-07"
        ixy="-1.51291789632062E-06"
        ixz="6.23596792173211E-22"
        iyy="7.86259408054763E-06"
        iyz="6.30276637663022E-22"
        izz="8.19546630464294E-06" />
    </inertial>
    <visual>
      <origin
        xyz="0 0 0"
        rpy="0 0 0" />
      <geometry>
        <mesh
          filename="package://audix/meshes/left_link5.STL" />
      </geometry>
      <material
        name="">
        <color
          rgba="0.792156862745098 0.819607843137255 0.933333333333333 1" />
      </material>
    </visual>
    <collision>
      <origin
        xyz="0 0 0"
        rpy="0 0 0" />
      <geometry>
        <mesh
          filename="package://audix/meshes/left_link5.STL" />
      </geometry>
    </collision>
  </link>
  <joint
    name="left_joint5"
    type="revolute">
    <origin
      xyz="0.117803138552813 0.0228565208880058 0.00499999999999967"
      rpy="3.14159265358979 0 3.14159265358979" />
    <parent
      link="left_link4" />
    <child
      link="left_link5" />
    <axis
      xyz="0 0 -1" />
    <limit
      lower="0"
      upper="0"
      effort="0"
      velocity="0" />
  </joint>
  <link
    name="camera_link">
    <inertial>
      <origin
        xyz="-0.0682144048132187 0.0215672397949688 -0.0429610406081863"
        rpy="0 0 0" />
      <mass
        value="0.354470228585855" />
      <inertia
        ixx="0.00034118534551311"
        ixy="5.38220140605918E-05"
        ixz="1.84999678385051E-08"
        iyy="0.000709048005585155"
        iyz="-3.64345991315383E-09"
        izz="0.000433758076720855" />
    </inertial>
    <visual>
      <origin
        xyz="0 0 0"
        rpy="0 0 0" />
      <geometry>
        <mesh
          filename="package://audix/meshes/camera_link.STL" />
      </geometry>
      <material
        name="">
        <color
          rgba="0.792156862745098 0.819607843137255 0.933333333333333 1" />
      </material>
    </visual>
    <collision>
      <origin
        xyz="0 0 0"
        rpy="0 0 0" />
      <geometry>
        <mesh
          filename="package://audix/meshes/camera_link.STL" />
      </geometry>
    </collision>
  </link>
  <joint
    name="camera_joint"
    type="revolute">
    <origin
      xyz="0.117803138552453 0.0228565208887948 0.0849999999999819"
      rpy="0 0 0" />
    <parent
      link="left_link5" />
    <child
      link="camera_link" />
    <axis
      xyz="0 0 -1" />
    <limit
      lower="0"
      upper="0"
      effort="0"
      velocity="0" />
  </joint>
  <link
    name="right_link2">
    <inertial>
      <origin
        xyz="0.0589015692764303 0.0114282604443792 1.93178806284777E-14"
        rpy="0 0 0" />
      <mass
        value="0.00615413438956677" />
      <inertia
        ixx="3.58514450684052E-07"
        ixy="-1.51291789623516E-06"
        ixz="8.54378013756915E-21"
        iyy="7.86259408058212E-06"
        iyz="1.68871254201842E-21"
        izz="8.19546630464297E-06" />
    </inertial>
    <visual>
      <origin
        xyz="0 0 0"
        rpy="0 0 0" />
      <geometry>
        <mesh
          filename="package://audix/meshes/right_link2.STL" />
      </geometry>
      <material
        name="">
        <color
          rgba="0.792156862745098 0.819607843137255 0.933333333333333 1" />
      </material>
    </visual>
    <collision>
      <origin
        xyz="0 0 0"
        rpy="0 0 0" />
      <geometry>
        <mesh
          filename="package://audix/meshes/right_link2.STL" />
      </geometry>
    </collision>
  </link>
  <joint
    name="right_joint2"
    type="continuous">
    <origin
      xyz="0.0200000000000368 0.0375000000000166 0.0424999999993435"
      rpy="1.5707963267949 0 0" />
    <parent
      link="scissors_lift_base" />
    <child
      link="right_link2" />
    <axis
      xyz="0 0 1" />
  </joint>
  <link
    name="right_link3">
    <inertial>
      <origin
        xyz="0.0589015692762507 0.0114282604443728 -1.98729921407903E-14"
        rpy="0 0 0" />
      <mass
        value="0.00615413438956667" />
      <inertia
        ixx="3.5851445071848E-07"
        ixy="-1.51291789632053E-06"
        ixz="7.29080406010438E-21"
        iyy="7.86259408054756E-06"
        iyz="1.44738514383463E-21"
        izz="8.19546630464284E-06" />
    </inertial>
    <visual>
      <origin
        xyz="0 0 0"
        rpy="0 0 0" />
      <geometry>
        <mesh
          filename="package://audix/meshes/right_link3.STL" />
      </geometry>
      <material
        name="">
        <color
          rgba="0.792156862745098 0.819607843137255 0.933333333333333 1" />
      </material>
    </visual>
    <collision>
      <origin
        xyz="0 0 0"
        rpy="0 0 0" />
      <geometry>
        <mesh
          filename="package://audix/meshes/right_link3.STL" />
      </geometry>
    </collision>
  </link>
  <joint
    name="right_joint3"
    type="revolute">
    <origin
      xyz="0.117803138552811 0.0228565208881228 -0.00500000000000023"
      rpy="3.14159265358979 0 3.14159265358979" />
    <parent
      link="right_link2" />
    <child
      link="right_link3" />
    <axis
      xyz="0 0 -1" />
    <limit
      lower="0"
      upper="0"
      effort="0"
      velocity="0" />
  </joint>
  <link
    name="right_link6">
    <inertial>
      <origin
        xyz="0.0589015692766905 0.0114282604443346 2.16493489801906E-14"
        rpy="0 0 0" />
      <mass
        value="0.0061541343895667" />
      <inertia
        ixx="3.5851445068419E-07"
        ixy="-1.51291789623549E-06"
        ixz="-4.14732094498514E-20"
        iyy="7.86259408058184E-06"
        iyz="-8.66039973901714E-21"
        izz="8.19546630464283E-06" />
    </inertial>
    <visual>
      <origin
        xyz="0 0 0"
        rpy="0 0 0" />
      <geometry>
        <mesh
          filename="package://audix/meshes/right_link6.STL" />
      </geometry>
      <material
        name="">
        <color
          rgba="0.792156862745098 0.819607843137255 0.933333333333333 1" />
      </material>
    </visual>
    <collision>
      <origin
        xyz="0 0 0"
        rpy="0 0 0" />
      <geometry>
        <mesh
          filename="package://audix/meshes/right_link6.STL" />
      </geometry>
    </collision>
  </link>
  <joint
    name="right_joint6"
    type="revolute">
    <origin
      xyz="0.117803138552816 0.0228565208881623 -0.00499999999999978"
      rpy="-3.14159265358979 0 -3.14159265358979" />
    <parent
      link="right_link3" />
    <child
      link="right_link6" />
    <axis
      xyz="0 0 -1" />
    <limit
      lower="0"
      upper="0"
      effort="0"
      velocity="0" />
  </joint>
  <link
    name="left_link2">
    <inertial>
      <origin
        xyz="0.0589015692764191 0.0114282604443155 2.27595720048157E-14"
        rpy="0 0 0" />
      <mass
        value="0.00615413438956668" />
      <inertia
        ixx="3.58514450684153E-07"
        ixy="-1.5129178962354E-06"
        ixz="-1.01209449508776E-19"
        iyy="7.86259408058185E-06"
        iyz="-2.02050891369746E-20"
        izz="8.19546630464281E-06" />
    </inertial>
    <visual>
      <origin
        xyz="0 0 0"
        rpy="0 0 0" />
      <geometry>
        <mesh
          filename="package://audix/meshes/left_link2.STL" />
      </geometry>
      <material
        name="">
        <color
          rgba="0.792156862745098 0.819607843137255 0.933333333333333 1" />
      </material>
    </visual>
    <collision>
      <origin
        xyz="0 0 0"
        rpy="0 0 0" />
      <geometry>
        <mesh
          filename="package://audix/meshes/left_link2.STL" />
      </geometry>
    </collision>
  </link>
  <joint
    name="left_joint2"
    type="revolute">
    <origin
      xyz="0.0200000000000404 -0.0374999999999837 0.0424999999994037"
      rpy="1.5707963267949 0 0" />
    <parent
      link="scissors_lift_base" />
    <child
      link="left_link2" />
    <axis
      xyz="0 0 1" />
    <limit
      lower="0"
      upper="0"
      effort="0"
      velocity="0" />
  </joint>
  <link
    name="left_link3">
    <inertial>
      <origin
        xyz="0.0589015692762586 0.0114282604443113 -2.42028619368284E-14"
        rpy="0 0 0" />
      <mass
        value="0.00615413438956668" />
      <inertia
        ixx="3.58514450718563E-07"
        ixy="-1.51291789632074E-06"
        ixz="-4.556820498975E-20"
        iyy="7.8625940805475E-06"
        iyz="-8.14298803333981E-21"
        izz="8.19546630464287E-06" />
    </inertial>
    <visual>
      <origin
        xyz="0 0 0"
        rpy="0 0 0" />
      <geometry>
        <mesh
          filename="package://audix/meshes/left_link3.STL" />
      </geometry>
      <material
        name="">
        <color
          rgba="0.792156862745098 0.819607843137255 0.933333333333333 1" />
      </material>
    </visual>
    <collision>
      <origin
        xyz="0 0 0"
        rpy="0 0 0" />
      <geometry>
        <mesh
          filename="package://audix/meshes/left_link3.STL" />
      </geometry>
    </collision>
  </link>
  <joint
    name="left_joint3"
    type="revolute">
    <origin
      xyz="0.117803138552808 0.0228565208880964 0.00499999999999923"
      rpy="3.14159265358979 0 3.14159265358979" />
    <parent
      link="left_link2" />
    <child
      link="left_link3" />
    <axis
      xyz="0 0 -1" />
    <limit
      lower="0"
      upper="0"
      effort="0"
      velocity="0" />
  </joint>
  <link
    name="left_link6">
    <inertial>
      <origin
        xyz="0.0589015692766959 0.0114282604442972 2.08721928629529E-14"
        rpy="0 0 0" />
      <mass
        value="0.00615413438956669" />
      <inertia
        ixx="3.58514450683972E-07"
        ixy="-1.51291789623495E-06"
        ixz="-4.1402050331523E-20"
        iyy="7.86259408058204E-06"
        iyz="-8.58086618358921E-21"
        izz="8.19546630464282E-06" />
    </inertial>
    <visual>
      <origin
        xyz="0 0 0"
        rpy="0 0 0" />
      <geometry>
        <mesh
          filename="package://audix/meshes/left_link6.STL" />
      </geometry>
      <material
        name="">
        <color
          rgba="0.792156862745098 0.819607843137255 0.933333333333333 1" />
      </material>
    </visual>
    <collision>
      <origin
        xyz="0 0 0"
        rpy="0 0 0" />
      <geometry>
        <mesh
          filename="package://audix/meshes/left_link6.STL" />
      </geometry>
    </collision>
  </link>
  <joint
    name="left_joint6"
    type="revolute">
    <origin
      xyz="0.11780313855282 0.0228565208881415 0.00499999999999901"
      rpy="-3.14159265358979 0 -3.14159265358979" />
    <parent
      link="left_link3" />
    <child
      link="left_link6" />
    <axis
      xyz="0 0 -1" />
    <limit
      lower="0"
      upper="0"
      effort="0"
      velocity="0" />
  </joint>
  <link
    name="top_stud_link">
    <inertial>
      <origin
        xyz="-7.50090308754281E-08 -7.19407883709167E-07 -1.61848112906204E-06"
        rpy="0 0 0" />
      <mass
        value="0.00137057236420411" />
      <inertia
        ixx="1.36300723783461E-06"
        ixy="1.13583038164696E-11"
        ixz="-2.26204747684194E-13"
        iyy="2.72084887040146E-09"
        iyz="1.07269797862821E-22"
        izz="1.36300707987298E-06" />
    </inertial>
    <visual>
      <origin
        xyz="0 0 0"
        rpy="0 0 0" />
      <geometry>
        <mesh
          filename="package://audix/meshes/top_stud_link.STL" />
      </geometry>
      <material
        name="">
        <color
          rgba="0.776470588235294 0.756862745098039 0.737254901960784 1" />
      </material>
    </visual>
    <collision>
      <origin
        xyz="0 0 0"
        rpy="0 0 0" />
      <geometry>
        <mesh
          filename="package://audix/meshes/top_stud_link.STL" />
      </geometry>
    </collision>
  </link>
  <joint
    name="top_stud_joint"
    type="prismatic">
    <origin
      xyz="0.117801346067773 0.0228566574753921 -0.0371507194078791"
      rpy="-1.5707963267949 0 1.5707963267949" />
    <parent
      link="left_link6" />
    <child
      link="top_stud_link" />
    <axis
      xyz="0 0 1" />
    <limit
      lower="0"
      upper="0"
      effort="0"
      velocity="0" />
  </joint>

  <link name="RobotBody" />

  <joint name="robot_body_joint" type="fixed">
    <origin xyz="0 0 0" rpy="0 0 0" />
    <parent link="base_link" />
    <child link="RobotBody" />
  </joint>

  <link name="imu_link">
    <inertial>
      <mass value="0.05" />
      <origin xyz="0 0 0" rpy="0 0 0" />
      <inertia ixx="1e-5" ixy="0" ixz="0" iyy="1e-5" iyz="0" izz="1e-5" />
    </inertial>
    <visual>
      <geometry>
        <box size="0.02 0.02 0.01" />
      </geometry>
    </visual>
    <collision>
      <geometry>
        <box size="0.02 0.02 0.01" />
      </geometry>
    </collision>
  </link>

  <joint name="imu_joint" type="fixed">
    <origin xyz="0 0 0.05" rpy="0 0 0" />
    <parent link="RobotBody" />
    <child link="imu_link" />
  </joint>

  <link name="ultrasonic_link">
    <visual>
      <geometry>
        <cylinder radius="0.03" length="0.05" />
      </geometry>
    </visual>
    <collision>
      <geometry>
        <cylinder radius="0.03" length="0.05" />
      </geometry>
    </collision>
    <inertial>
      <mass value="0.1" />
      <origin xyz="0 0 0" rpy="0 0 0" />
      <inertia ixx="1e-5" ixy="0" ixz="0" iyy="1e-5" iyz="0" izz="1e-5" />
    </inertial>
  </link>

  <joint name="ultrasonic_joint" type="fixed">
    <parent link="RobotBody" />
    <child link="ultrasonic_link" />
    <origin xyz="0.15 0 0.07" rpy="0 0 0" />
  </joint>

  <ros2_control name="AudixSystem" type="system">
    <hardware>
      <plugin>gz_ros2_control/GazeboSimSystem</plugin>
    </hardware>

    <joint name="front_left_wheel_joint">
      <command_interface name="velocity" />
      <state_interface name="position" />
      <state_interface name="velocity" />
    </joint>
    <joint name="back_left_wheel_joint">
      <command_interface name="velocity" />
      <state_interface name="position" />
      <state_interface name="velocity" />
    </joint>
    <joint name="front_right_wheel_joint">
      <command_interface name="velocity" />
      <state_interface name="position" />
      <state_interface name="velocity" />
    </joint>
    <joint name="back_right_wheel_joint">
      <command_interface name="velocity" />
      <state_interface name="position" />
      <state_interface name="velocity" />
    </joint>
  </ros2_control>

  <gazebo>
    <plugin filename="gz_ros2_control-system" name="gz_ros2_control::GazeboSimROS2ControlPlugin">
      <parameters>$(find audix)/config/controllers.yaml</parameters>
    </plugin>
  </gazebo>

  <gazebo reference="imu_link">
    <sensor name="imu_sensor" type="imu">
      <always_on>true</always_on>
      <update_rate>50</update_rate>
      <topic>imu</topic>
      <plugin filename="gz-sim-imu-system" name="gz::sim::systems::Imu" />
    </sensor>
  </gazebo>

  <gazebo reference="ultrasonic_link">
    <sensor name="lidar_sensor" type="gpu_lidar">
      <always_on>1</always_on>
      <update_rate>50</update_rate>
      <topic>scan</topic>
      <ray>
        <scan>
          <horizontal>
            <samples>640</samples>
            <resolution>1</resolution>
            <min_angle>0</min_angle>
            <max_angle>0</max_angle>
          </horizontal>
          <vertical>
            <samples>1</samples>
            <resolution>0.01</resolution>
            <min_angle>0</min_angle>
            <max_angle>0</max_angle>
          </vertical>
        </scan>
        <range>
          <min>0.08</min>
          <max>10.0</max>
          <resolution>0.01</resolution>
        </range>
      </ray>
      <visualize>true</visualize>
    </sensor>
  </gazebo>
</robot>